2024-08-07 08:48:44,439 - main - ERROR - Some error occurred
Traceback (most recent call last):
  File "D:\Sites\sinus\server\main.py", line 46, in error
    raise ValueError("Some error occurred")
ValueError: Some error occurred
